Workbook

Sheet Cover
A1: EBA Credit Risk Stress Model
A2: NPE-shock stress test of CET1 headroom, 11 EU banks, reference date 30 June 2025
A4: Purpose | B4: Estimates how far each bank's CET1 ratio sits above its own CET1 requirement (MDA trigger) after a rise in non-performing exposures consistent with the ECB 2025 stress test paths. Headline = instant loss absorption by June 2025 capital (A19); a second layer adds earnings under EBA tax and payout rules.
A5: Data | B5: EBA 2025 EU-wide Transparency Exercise, reference period 202506 (tr_cre.csv, tr_oth.csv). Inputs are produced by query Q33 in queries.sql. Amounts in EUR millions.
A6: Units | B6: Amounts EUR mn. Ratios and shocks stored as fractions and shown as percentages. 'pp' = percentage points of RWA.
A7: Sheets | B7: Assumptions → Requirements → Bank Inputs → Stress (four scenarios) → Summary → Sensitivity → Notes.
A8: Colour code | B8: Blue text = hard-coded input or source data. Black = formula. Green = link to another sheet. Yellow fill = key assumption that drives results.
A9: How to use | B9: Change only blue cells on Assumptions (yellow-filled levers) or Requirements. All other cells recalculate.
A10: Scope | B10: 9 core banks plus Morgan Stanley Europe Holding SE are 'Core'. Revolut is a fintech reference case shown separately and excluded from medians. Kommuninvest is kept on Bank Inputs for reference but excluded from the stress run (see A14).
A11: Status | B11: Educational analysis of public data. Not investment advice and not a supervisory result.

Sheet Assumptions
A1: Assumptions register
A3: ID | B3: Assumption | C3: Value | D3: Source / rationale
A4: A1 | B4: NPE shock, 1-year baseline (pp of gross loans) | C4: 0.008 | D4: Read from ECB report Chart 3.7 'NPE ratio at system level' (p. 27) by pixel measurement, calibrated to the published start (1.7%, end-2024) and adverse end-point (5.8%, end-2027, p. 26). Reading precision about ±0.1 pp; the Sensitivity sheet tests ±0.3 pp. Baseline path ≈ 2.5% at end-2025 vs 1.7% start.
A5: A2 | B5: NPE shock, 1-year adverse | C5: 0.012 | D5: Read from ECB report Chart 3.7 'NPE ratio at system level' (p. 27) by pixel measurement, calibrated to the published start (1.7%, end-2024) and adverse end-point (5.8%, end-2027, p. 26). Reading precision about ±0.1 pp; the Sensitivity sheet tests ±0.3 pp. Adverse path ≈ 2.9% at end-2025 vs 1.7% start.
A6: A3 | B6: NPE shock, 3-year baseline | C6: 0.024 | D6: Read from ECB report Chart 3.7 'NPE ratio at system level' (p. 27) by pixel measurement, calibrated to the published start (1.7%, end-2024) and adverse end-point (5.8%, end-2027, p. 26). Reading precision about ±0.1 pp; the Sensitivity sheet tests ±0.3 pp. Baseline path ≈ 4.1% at end-2027 vs 1.7% start.
A7: A4 | B7: NPE shock, 3-year adverse | C7: 0.041 | D7: ECB report p. 26: 'banks project a steady increase in the NPE ratio to 5.8% at the end of 2027' from 1.7%. ECB (2025) 2025 stress test of euro area banks – Final results, https://www.bankingsupervision.europa.eu/ecb/pub/pdf/ssm.Report_2025_Stress_Test_202508.en.pdf
A8: A5 | B8: Shock base | C8: Gross loans (performing + non-performing) | D8: Item 2520603, Perf_Status 1+2. The shock moves the NPE ratio by the stated pp, so it applies to the whole gross book. Same uniform system shock for every bank (see Notes, limitation L3).
A9: A6 | B9: Provisioning of new NPE | C9: Bank's own current NPE coverage | D9: Coverage = item 2520613 ÷ item 2520603 (Perf_Status 2). New NPE assumed provisioned at the bank's current rate.
A10: A7 | B10: RWA | C10: Held constant | D10: ECB 2025 adverse result: net CET1 depletion 4.0 pp, of which risk exposure amount growth 1.1 pp and loan losses 5.0 pp. Holding RWA constant isolates the credit-loss channel; it understates depletion (Notes, L2). ECB (2025) 2025 stress test of euro area banks – Final results, https://www.bankingsupervision.europa.eu/ecb/pub/pdf/ssm.Report_2025_Stress_Test_202508.en.pdf
A11: A8 | B11: Balance sheet | C11: Static | D11: Mirrors the static balance sheet assumption of the EBA/ECB exercise. EBA (2024) 2025 EU-wide stress test – Methodological note, https://www.eba.europa.eu/sites/default/files/2024-11/ee01efca-947b-43ae-b17d-20f9d4314e8e/2025%20EU-wide%20stress%20test%20-%20Methodological%20Note.pdf
A12: A9 | B12: Annualisation factor for H1 profit | C12: 2 | D12: Profit items at 202506 are half-year cumulative (n_quarters = 2).
A13: A10 | B13: Earnings capacity per year | C13: Annualised profit before tax | D13: Item 2520332 × A9. Profit before tax already carries the bank's ongoing impairment charge, so only the shock-driven provisions are added on top (avoids double counting).
A14: A11 | B14: Tax rate on positive pre-tax result | C14: 0.3 | D14: EBA methodological note, para. 32 (section 1.3.7): 'common simplified tax rate of 30%'. EBA (2024) 2025 EU-wide stress test – Methodological note, https://www.eba.europa.eu/sites/default/files/2024-11/ee01efca-947b-43ae-b17d-20f9d4314e8e/2025%20EU-wide%20stress%20test%20-%20Methodological%20Note.pdf
A15: A12 | B15: Tax on losses | C15: No tax credit | D15: Deferred tax assets arising from tax losses rely on future profitability and are deducted from CET1 (CRR Art. 36(1)(c)), so a loss reduces CET1 in full.
A16: A13 | B16: Payout ratio in profit years | C16: 0.3 | D16: EBA methodological note, Table 1 (section 1.3.12): baseline payout = declared policy, else max(30%, median 2020–24); same in adverse; 0% accepted in loss years. 2020–24 payouts are not in the data, so the 30% floor is used for every bank (Notes, L5).
A17: A14 | B17: Payout ratio in loss years | C17: 0 | D17: EBA methodological note, Table 1: zero payout accepted in loss years.
A18: A15 | B18: CET1 requirement | C18: Per-bank published requirement | D18: See Requirements sheet: bank SREP announcements or Pillar 3 EU KM1; CEC Bank uses a labelled fallback formula.
A19: A16 | B19: Kommuninvest | C19: Excluded from stress run | D19: Lends only to Swedish municipalities and regions (public-sector, 'low default' exposure). Its NPE stock is zero. ECB report (text under Chart 3.8): exposures to central banks, governments and financial institutions are 32% of exposures but about 6% of impairments as they are 'low default'.
A20: A17 | B20: Revolut | C20: Reference case | D20: Fintech business model; reported on its own line and excluded from the core median.
A21: A18 | B21: Horizon | C21: Single-period end state | D21: Provisions assumed spread evenly over the horizon, so annual and cumulative net results have the same sign; the payout rule can be applied to the cumulative result.
A22: A19 | B22: Headline view | C22: Instant loss absorption | D22: Shock provisions are charged against June 2025 CET1 with no earnings offset. Answers: can today's capital absorb the shock? Chosen as headline because the model does not stress revenues (Notes, L2); crediting run-rate profits would outweigh the credit shock and contradict the ECB result (adverse CET1 depletion 4.0 pp). The earnings offset (A9–A14) is reported as a second layer.
A24: Scenario table
A25: Code | B25: Scenario | C25: NPE shock | D25: Horizon (years)
A26: S1 | B26: 1-year baseline | C26: =$C$4 -> 0.008 | D26: 1
A27: S2 | B27: 1-year adverse | C27: =$C$5 -> 0.012 | D27: 1
A28: S3 | B28: 3-year baseline | C28: =$C$6 -> 0.024 | D28: 3
A29: S4 | B29: 3-year adverse | C29: =$C$7 -> 0.041 | D29: 3

Sheet Requirements
A1: CET1 requirements (MDA trigger) by bank
A2: Requirement excludes Pillar 2 Guidance. Values are the banks' own published figures unless marked FALLBACK.
A4: LEI | B4: Bank | C4: CET1 requirement | D4: Components / basis | E4: As of | F4: Source type | G4: Source URL
A5: 529900S9YO2JHTIIDG38 | B5: BAWAG Group | C5: 0.1033 | D5: CET1 requirement / MDA trigger (P2R 2.50 total) | E5: 2025-06-30 | F5: bank Q2 2025 investor data | G5: https://www.bawaggroup.com/resource/blob/104376/1acbccbaed725bf9bd662a22aa53747a/bawag-group-q2-2025-credit-update-final-data.pdf
A6: R0MUWSFPU8MPRO8K5P83 | B6: BNP Paribas | C6: 0.1029 | D6: P1 4.50 + P2R(CET1) 1.14 + CCoB 2.50 + G-SIB 1.50 + CCyB 0.65 | E6: 2025-01-01 | F6: bank SREP announcement | G6: https://invest.bnpparibas/en/document/notification-by-the-ecb-of-the-2024-supervisory-review-and-evaluation-process-srep
A7: 5493006QMFDDMYWIAM13 | B7: Banco Santander | C7: 0.0967 | D7: P1 4.50 + P2R(CET1) 0.98 + CCoB 2.50 + O-SII 1.25 + SyRB 0.04 + CCyB 0.40 | E7: 2025-01-01 | F7: bank SREP announcement | G7: https://www.investegate.co.uk/announcement/rns/banco-santander-s-a---bnc/srep-capital-requirements-2025/8604761
A8: 2138008AVF4W7FMW8W87 | B8: CEC Bank | C8: 0.122 | D8: FALLBACK: P1 4.50 + P2R(CET1) proxy 1.20 (ECB SSM average) + CCoB 2.50 + CCyB RO 1.00 + O-SII 1.00 + SyRB 2.00 (assumed still applied; last confirmed 2022) | E8: 2025-06-30 | F8: fallback formula | G8: https://www.cnsmro.ro/en/informatii-privind-lista-actualizata-a-bancilor-sistemice-si-amortizorul-pentru-alte-institutii-de-importanta-sistemica-amortizorul-o-sii-aplicabil-incepand-cu-1-aprilie-2025/
A9: 851WYGNLUQLFZBSYGB56 | B9: Commerzbank | C9: 0.1031 | D9: MDA threshold: P1 4.50 + P2R(CET1) 1.27 + CCoB 2.50 + O-SII 1.25 + CCyB 0.66 + SyRB 0.10 + AT1 shortfall 0.04 | E9: 2025-01-01 (pro forma at 2024-09-30) | F9: bank SREP announcement | G9: https://www.commerzbank.de/group/newsroom/press-releases/srep-2.html
A10: 7LTWFZYICNSX8D621K86 | B10: Deutsche Bank | C10: 0.1124 | D10: P1 4.50 + P2R(CET1) 1.63 + CCoB 2.50 + CCyB 0.48 + SyRB 0.13 + max(G-SII 1.50; O-SII 2.00) | E10: 2025-06-30 | F10: Pillar 3 EU KM1 | G10: https://investor-relations.db.com/files/documents/regulatory-reporting/2025/Pillar-3-Report-2Q2025.pdf
A11: FR969500TJ5KRTCJQWXH | B11: Groupe Crédit Agricole | C11: 0.098 | D11: P1 4.50 + P2R(CET1) + CCoB 2.50 + G-SIB 1.00 + CCyB ~0.77 + SyRB ~0.05 (P2R 1.80 total) | E11: 2025-01-01 | F11: bank SREP announcement | G11: https://mfn.se/one/a/credit-agricole/credit-agricole-sa-capital-notification-of-the-level-of-pillar-2-additional-requirement-009ecd29
A12: F0HUI1NY1AZMJMD8LP67 | B12: HSBC Continental Europe | C12: 0.097 | D12: Stated CET1 requirement excl. P2G (KM1: P2R(CET1) 1.5 + CBR 3.6) | E12: 2025-06-30 | F12: Pillar 3 EU KM1 | G12: https://echanges.dila.gouv.fr/OPENDATA/AMF/305/2025/09/FC305595282_20250905.pdf
A13: 549300NYKK9MWM7GGW15 | B13: ING Groep | C13: 0.1087 | D13: Fully loaded CET1 requirement incl. CCyB 0.94 and P2R 1.65 (total) | E13: 2025-01-01 | F13: bank SREP announcement | G13: https://ing.com/news/2024/12/ing-group-2024-srep-process-completed-1.html
A14: 549300C9KPZR0VZ16R05 | B14: Morgan Stanley Europe Holding SE | C14: 0.0956 | D14: P1 4.50 + P2R(CET1) 1.41 + CCoB 2.50 + CCyB 0.90 + O-SII 0.25 | E14: 2025-06-30 | F14: Pillar 3 EU KM1 | G14: https://www.morganstanley.com/content/dam/msdotcom/en/about-us-ir/pillar3/MSEHSE_Pillar_3_Disclosure_Report_30_June_2025_English.pdf
A15: 485100FX5Y9YLAQLNP12 | B15: Revolut Holdings Europe | C15: 0.0997 | D15: P1 4.50 + P2R(CET1) 2.08 + CCoB 2.50 + CCyB 0.89 | E15: 2025-06-30 | F15: Pillar 3 EU KM1 | G15: https://assets.revolut.com/pdf/Capital_Adequacy_Risk_management_RHE_Q2_2025

Sheet Bank Inputs
A1: Bank inputs, EBA Transparency Exercise 2025, period 202506 (EUR mn)
A2: Source query: query Q33 in queries.sql. Items: 2521010, 2520138, 2520102, 2520140 (oth); 2520603 Perf_Status 1/2 and 2520613 Perf_Status 2 (credit); 2520332, 2520333 (oth, H1 cumulative).
A4: LEI | B4: Bank | C4: Role | D4: Total assets | E4: RWA | F4: CET1 capital | G4: CET1 ratio (reported) | H4: Performing loans | I4: Non-performing loans | J4: Gross loans | K4: NPE provisions | L4: NPE ratio | M4: NPE coverage | N4: Profit before tax H1 | O4: Profit after tax H1 | P4: Annual profit before tax | Q4: Effective tax rate (info) | R4: CET1 ratio check | S4: CET1 requirement | T4: Headroom today
A5: 529900S9YO2JHTIIDG38 | B5: BAWAG Group | C5: Core | D5: 72765.138 | E5: 23505.442 | F5: 2949.5639 | G5: 0.1254843 | H5: 49249.607 | I5: 665.3407 | J5: =H5+I5 -> 49914.948 | K5: 277.71714 | L5: =IFERROR(I5/J5,0) -> 0.013329488 | M5: =IFERROR(K5/I5,"n/a") -> 0.41740591 | N5: 548.42208 | O5: 408.45709 | P5: =N5*Assumptions!$C$12 -> 1096.8442 | Q5: =IFERROR(1-O5/N5,"n/a") -> 0.25521399 | R5: =F5/E5 -> 0.1254843 | S5: =Requirements!$C$5 -> 0.1033 | T5: =R5-S5 -> 0.022184299
A6: R0MUWSFPU8MPRO8K5P83 | B6: BNP Paribas | C6: Core | D6: 2573933.9 | E6: 788849.56 | F6: 98280.564 | G6: 0.12458721 | H6: 936747.65 | I6: 26870.413 | J6: =H6+I6 -> 963618.06 | K6: 13033.49 | L6: =IFERROR(I6/J6,0) -> 0.027884921 | M6: =IFERROR(K6/I6,"n/a") -> 0.48504985 | N6: 8648.6725 | O6: 6498.7684 | P6: =N6*Assumptions!$C$12 -> 17297.345 | Q6: =IFERROR(1-O6/N6,"n/a") -> 0.24858198 | R6: =F6/E6 -> 0.12458721 | S6: =Requirements!$C$6 -> 0.1029 | T6: =R6-S6 -> 0.021687209
A7: 5493006QMFDDMYWIAM13 | B7: Banco Santander | C7: Core | D7: 1797909.9 | E7: 625750.27 | F7: 81252.907 | G7: 0.12984878 | H7: 1037662.7 | I7: 35924.454 | J7: =H7+I7 -> 1073587.2 | K7: 14243.98 | L7: =IFERROR(I7/J7,0) -> 0.033462074 | M7: =IFERROR(K7/I7,"n/a") -> 0.39649816 | N7: 9089.942 | O7: 6737.048 | P7: =N7*Assumptions!$C$12 -> 18179.884 | Q7: =IFERROR(1-O7/N7,"n/a") -> 0.25884588 | R7: =F7/E7 -> 0.12984878 | S7: =Requirements!$C$7 -> 0.0967 | T7: =R7-S7 -> 0.033148777
A8: 2138008AVF4W7FMW8W87 | B8: CEC Bank | C8: Core | D8: 19594.395 | E8: 5426.0227 | F8: 1300.5567 | G8: 0.23968878 | H8: 7549.0833 | I8: 558.10733 | J8: =H8+I8 -> 8107.1907 | K8: 303.09855 | L8: =IFERROR(I8/J8,0) -> 0.068841027 | M8: =IFERROR(K8/I8,"n/a") -> 0.5430829 | N8: 74.961782 | O8: 60.302222 | P8: =N8*Assumptions!$C$12 -> 149.92356 | Q8: =IFERROR(1-O8/N8,"n/a") -> 0.19556045 | R8: =F8/E8 -> 0.23968878 | S8: =Requirements!$C$8 -> 0.122 | T8: =R8-S8 -> 0.11768878
A9: 851WYGNLUQLFZBSYGB56 | B9: Commerzbank | C9: Core | D9: 599092.1 | E9: 176124.49 | F9: 25641.99 | G9: 0.14559015 | H9: 357348.47 | I9: 5035.6792 | J9: =H9+I9 -> 362384.14 | K9: 2199.6579 | L9: =IFERROR(I9/J9,0) -> 0.01389597 | M9: =IFERROR(K9/I9,"n/a") -> 0.43681454 | N9: 1859.0131 | O9: 1405.9096 | P9: =N9*Assumptions!$C$12 -> 3718.0263 | Q9: =IFERROR(1-O9/N9,"n/a") -> 0.24373339 | R9: =F9/E9 -> 0.14559015 | S9: =Requirements!$C$9 -> 0.1031 | T9: =R9-S9 -> 0.042490148
A10: 7LTWFZYICNSX8D621K86 | B10: Deutsche Bank | C10: Core | D10: 1395879.9 | E10: 340805.06 | F10: 48521.573 | G10: 0.14237339 | H10: 717860.63 | I10: 14914.508 | J10: =H10+I10 -> 732775.14 | K10: 4642.6954 | L10: =IFERROR(I10/J10,0) -> 0.020353458 | M10: =IFERROR(K10/I10,"n/a") -> 0.3112872 | N10: 5243.5438 | O10: 3736.6346 | P10: =N10*Assumptions!$C$12 -> 10487.088 | Q10: =IFERROR(1-O10/N10,"n/a") -> 0.28738374 | R10: =F10/E10 -> 0.14237339 | S10: =Requirements!$C$10 -> 0.1124 | T10: =R10-S10 -> 0.029973393
A11: FR969500TJ5KRTCJQWXH | B11: Groupe Crédit Agricole | C11: Core | D11: 2187749.1 | E11: 649013.18 | F11: 114107.25 | G11: 0.17581654 | H11: 1319100.9 | I11: 26431.749 | J11: =H11+I11 -> 1345532.7 | K11: 12915.303 | L11: =IFERROR(I11/J11,0) -> 0.019644079 | M11: =IFERROR(K11/I11,"n/a") -> 0.48862838 | N11: 6666.8189 | O11: 5346.9399 | P11: =N11*Assumptions!$C$12 -> 13333.638 | Q11: =IFERROR(1-O11/N11,"n/a") -> 0.19797733 | R11: =F11/E11 -> 0.17581654 | S11: =Requirements!$C$11 -> 0.098 | T11: =R11-S11 -> 0.077816535
A12: F0HUI1NY1AZMJMD8LP67 | B12: HSBC Continental Europe | C12: Core | D12: 257233.54 | E12: 67610.082 | F12: 10461.292 | G12: 0.15472976 | H12: 89240.027 | I12: 1407.361 | J12: =H12+I12 -> 90647.388 | K12: 369.976 | L12: =IFERROR(I12/J12,0) -> 0.015525665 | M12: =IFERROR(K12/I12,"n/a") -> 0.26288635 | N12: 498.028 | O12: 418.412 | P12: =N12*Assumptions!$C$12 -> 996.056 | Q12: =IFERROR(1-O12/N12,"n/a") -> 0.1598625 | R12: =F12/E12 -> 0.15472976 | S12: =Requirements!$C$12 -> 0.097 | T12: =R12-S12 -> 0.057729757
A13: 549300NYKK9MWM7GGW15 | B13: ING Groep | C13: Core | D13: 1086759.8 | E13: 335803.78 | F13: 44534.032 | G13: 0.13261921 | H13: 815802.57 | I13: 12329.485 | J13: =H13+I13 -> 828132.06 | K13: 4184.136 | L13: =IFERROR(I13/J13,0) -> 0.014888308 | M13: =IFERROR(K13/I13,"n/a") -> 0.33936016 | N13: 4493.034 | O13: 3256.378 | P13: =N13*Assumptions!$C$12 -> 8986.068 | Q13: =IFERROR(1-O13/N13,"n/a") -> 0.27523851 | R13: =F13/E13 -> 0.13261921 | S13: =Requirements!$C$13 -> 0.1087 | T13: =R13-S13 -> 0.023919212
A14: 549300C9KPZR0VZ16R05 | B14: Morgan Stanley Europe Holding SE | C14: Core | D14: 110484.44 | E14: 34950.148 | F14: 6290.7774 | G14: 0.17999287 | H14: 37754.86 | I14: 6.9650982 | J14: =H14+I14 -> 37761.825 | K14: 2.5248409 | L14: =IFERROR(I14/J14,0) -> 0.00018444813 | M14: =IFERROR(K14/I14,"n/a") -> 0.36249897 | N14: 269.45386 | O14: 195.80011 | P14: =N14*Assumptions!$C$12 -> 538.90771 | Q14: =IFERROR(1-O14/N14,"n/a") -> 0.27334457 | R14: =F14/E14 -> 0.17999287 | S14: =Requirements!$C$14 -> 0.0956 | T14: =R14-S14 -> 0.084392871
A15: 485100FX5Y9YLAQLNP12 | B15: Revolut Holdings Europe | C15: Reference case | D15: 27385.381 | E15: 4141.1182 | F15: 1297.1554 | G15: 0.31323795 | H15: 7056.5306 | I15: 57.095086 | J15: =H15+I15 -> 7113.6257 | K15: 45.985816 | L15: =IFERROR(I15/J15,0) -> 0.0080261583 | M15: =IFERROR(K15/I15,"n/a") -> 0.8054251 | N15: 133.5668 | O15: 102.923 | P15: =N15*Assumptions!$C$12 -> 267.1336 | Q15: =IFERROR(1-O15/N15,"n/a") -> 0.22942678 | R15: =F15/E15 -> 0.31323795 | S15: =Requirements!$C$15 -> 0.0997 | T15: =R15-S15 -> 0.21353795
A16: EV2XZWMLLXF2QRX0CD47 | B16: Kommuninvest | C16: Excluded | D16: 59929.185 | E16: 302.29875 | F16: 1066.0894 | G16: 3.5266087 | H16: 52612.737 | I16: 0 | J16: =H16+I16 -> 52612.737 | K16: 0 | L16: =IFERROR(I16/J16,0) -> 0 | M16: =IFERROR(K16/I16,"n/a") -> n/a | N16: 4.369265 | O16: 3.220575 | P16: =N16*Assumptions!$C$12 -> 8.7385299 | Q16: =IFERROR(1-O16/N16,"n/a") -> 0.26290234 | R16: =F16/E16 -> 3.5266087 | S16: n/a | T16: n/a
A18: Note: Morgan Stanley Europe's coverage rests on EUR 7 mn of NPE, so its coverage estimate is statistically weak (Notes, L7). Kommuninvest coverage is undefined (no NPE).

Sheet Stress
A1: Stress results by scenario
A2: HEADLINE (columns F–K): instant loss absorption, shock provisions charged against June 2025 CET1 with no earnings offset (A19). SECOND LAYER (columns L–S): earnings offset under EBA tax and payout rules; optimistic because revenues are not stressed (Notes, L2).
A4: S1 · 1-year baseline | C4: Shock | D4: =Assumptions!$C$26 -> 0.008 | E4: Horizon (yrs) | F4: =Assumptions!$D$26 -> 1
A5: Bank | B5: Role | C5: Stressed NPE ratio | D5: Incremental NPE | E5: Incremental provisions | F5: HEADLINE: Stressed CET1 | G5: Stressed CET1 ratio | H5: Change in ratio (pp) | I5: CET1 requirement | J5: Headroom (pp) | K5: Below requirement? | L5: Earnings over horizon | M5: Pre-tax result | N5: Tax | O5: Net result | P5: Distributions | Q5: Stressed CET1 (with earnings) | R5: Stressed CET1 ratio (with earnings) | S5: Headroom with earnings (pp)
A6: ='Bank Inputs'!B5 -> BAWAG Group | B6: ='Bank Inputs'!C5 -> Core | C6: ='Bank Inputs'!L5+$D$4 -> 0.021329488 | D6: =$D$4*'Bank Inputs'!J5 -> 399.31958 | E6: =D6*'Bank Inputs'!M5 -> 166.67835 | F6: ='Bank Inputs'!F5-E6 -> 2782.8856 | G6: =F6/'Bank Inputs'!E5 -> 0.11839325 | H6: =G6-'Bank Inputs'!R5 -> -0.0070910537 | I6: ='Bank Inputs'!S5 -> 0.1033 | J6: =G6-I6 -> 0.015093246 | K6: =IF(J6<0,"YES","no") -> no | L6: ='Bank Inputs'!P5*$F$4 -> 1096.8442 | M6: =L6-E6 -> 930.16581 | N6: =MAX(M6,0)*Assumptions!$C$14 -> 279.04974 | O6: =M6-N6 -> 651.11606 | P6: =IF(O6>0,O6*Assumptions!$C$16,Assumptions!$C$17*0) -> 195.33482 | Q6: ='Bank Inputs'!F5+O6-P6 -> 3405.3452 | R6: =Q6/'Bank Inputs'!E5 -> 0.14487476 | S6: =R6-I6 -> 0.041574756
A7: ='Bank Inputs'!B6 -> BNP Paribas | B7: ='Bank Inputs'!C6 -> Core | C7: ='Bank Inputs'!L6+$D$4 -> 0.035884921 | D7: =$D$4*'Bank Inputs'!J6 -> 7708.9445 | E7: =D7*'Bank Inputs'!M6 -> 3739.2224 | F7: ='Bank Inputs'!F6-E7 -> 94541.342 | G7: =F7/'Bank Inputs'!E6 -> 0.11984711 | H7: =G7-'Bank Inputs'!R6 -> -0.0047400957 | I7: ='Bank Inputs'!S6 -> 0.1029 | J7: =G7-I7 -> 0.016947113 | K7: =IF(J7<0,"YES","no") -> no | L7: ='Bank Inputs'!P6*$F$4 -> 17297.345 | M7: =L7-E7 -> 13558.123 | N7: =MAX(M7,0)*Assumptions!$C$14 -> 4067.4368 | O7: =M7-N7 -> 9490.6858 | P7: =IF(O7>0,O7*Assumptions!$C$16,Assumptions!$C$17*0) -> 2847.2057 | Q7: ='Bank Inputs'!F6+O7-P7 -> 104924.04 | R7: =Q7/'Bank Inputs'!E6 -> 0.13300894 | S7: =R7-I7 -> 0.030108942
A8: ='Bank Inputs'!B7 -> Banco Santander | B8: ='Bank Inputs'!C7 -> Core | C8: ='Bank Inputs'!L7+$D$4 -> 0.041462074 | D8: =$D$4*'Bank Inputs'!J7 -> 8588.6975 | E8: =D8*'Bank Inputs'!M7 -> 3405.4028 | F8: ='Bank Inputs'!F7-E8 -> 77847.504 | G8: =F8/'Bank Inputs'!E7 -> 0.12440667 | H8: =G8-'Bank Inputs'!R7 -> -0.0054421116 | I8: ='Bank Inputs'!S7 -> 0.0967 | J8: =G8-I8 -> 0.027706665 | K8: =IF(J8<0,"YES","no") -> no | L8: ='Bank Inputs'!P7*$F$4 -> 18179.884 | M8: =L8-E8 -> 14774.481 | N8: =MAX(M8,0)*Assumptions!$C$14 -> 4432.3444 | O8: =M8-N8 -> 10342.137 | P8: =IF(O8>0,O8*Assumptions!$C$16,Assumptions!$C$17*0) -> 3102.6411 | Q8: ='Bank Inputs'!F7+O8-P8 -> 88492.403 | R8: =Q8/'Bank Inputs'!E7 -> 0.14141808 | S8: =R8-I8 -> 0.044718082
A9: ='Bank Inputs'!B8 -> CEC Bank | B9: ='Bank Inputs'!C8 -> Core | C9: ='Bank Inputs'!L8+$D$4 -> 0.076841027 | D9: =$D$4*'Bank Inputs'!J8 -> 64.857525 | E9: =D9*'Bank Inputs'!M8 -> 35.223013 | F9: ='Bank Inputs'!F8-E9 -> 1265.3337 | G9: =F9/'Bank Inputs'!E8 -> 0.23319728 | H9: =G9-'Bank Inputs'!R8 -> -0.0064914975 | I9: ='Bank Inputs'!S8 -> 0.122 | J9: =G9-I9 -> 0.11119728 | K9: =IF(J9<0,"YES","no") -> no | L9: ='Bank Inputs'!P8*$F$4 -> 149.92356 | M9: =L9-E9 -> 114.70055 | N9: =MAX(M9,0)*Assumptions!$C$14 -> 34.410165 | O9: =M9-N9 -> 80.290385 | P9: =IF(O9>0,O9*Assumptions!$C$16,Assumptions!$C$17*0) -> 24.087116 | Q9: ='Bank Inputs'!F8+O9-P9 -> 1356.76 | R9: =Q9/'Bank Inputs'!E8 -> 0.25004687 | S9: =R9-I9 -> 0.12804687
A10: ='Bank Inputs'!B9 -> Commerzbank | B10: ='Bank Inputs'!C9 -> Core | C10: ='Bank Inputs'!L9+$D$4 -> 0.02189597 | D10: =$D$4*'Bank Inputs'!J9 -> 2899.0732 | E10: =D10*'Bank Inputs'!M9 -> 1266.3573 | F10: ='Bank Inputs'!F9-E10 -> 24375.633 | G10: =F10/'Bank Inputs'!E9 -> 0.13840002 | H10: =G10-'Bank Inputs'!R9 -> -0.0071901264 | I10: ='Bank Inputs'!S9 -> 0.1031 | J10: =G10-I10 -> 0.035300021 | K10: =IF(J10<0,"YES","no") -> no | L10: ='Bank Inputs'!P9*$F$4 -> 3718.0263 | M10: =L10-E10 -> 2451.6689 | N10: =MAX(M10,0)*Assumptions!$C$14 -> 735.50068 | O10: =M10-N10 -> 1716.1683 | P10: =IF(O10>0,O10*Assumptions!$C$16,Assumptions!$C$17*0) -> 514.85048 | Q10: ='Bank Inputs'!F9+O10-P10 -> 26843.308 | R10: =Q10/'Bank Inputs'!E9 -> 0.15241099 | S10: =R10-I10 -> 0.049310992
A11: ='Bank Inputs'!B10 -> Deutsche Bank | B11: ='Bank Inputs'!C10 -> Core | C11: ='Bank Inputs'!L10+$D$4 -> 0.028353458 | D11: =$D$4*'Bank Inputs'!J10 -> 5862.2011 | E11: =D11*'Bank Inputs'!M10 -> 1824.8282 | F11: ='Bank Inputs'!F10-E11 -> 46696.745 | G11: =F11/'Bank Inputs'!E10 -> 0.13701893 | H11: =G11-'Bank Inputs'!R10 -> -0.0053544632 | I11: ='Bank Inputs'!S10 -> 0.1124 | J11: =G11-I11 -> 0.02461893 | K11: =IF(J11<0,"YES","no") -> no | L11: ='Bank Inputs'!P10*$F$4 -> 10487.088 | M11: =L11-E11 -> 8662.2595 | N11: =MAX(M11,0)*Assumptions!$C$14 -> 2598.6779 | O11: =M11-N11 -> 6063.5817 | P11: =IF(O11>0,O11*Assumptions!$C$16,Assumptions!$C$17*0) -> 1819.0745 | Q11: ='Bank Inputs'!F10+O11-P11 -> 52766.08 | R11: =Q11/'Bank Inputs'!E10 -> 0.15482775 | S11: =R11-I11 -> 0.042427748
A12: ='Bank Inputs'!B11 -> Groupe Crédit Agricole | B12: ='Bank Inputs'!C11 -> Core | C12: ='Bank Inputs'!L11+$D$4 -> 0.027644079 | D12: =$D$4*'Bank Inputs'!J11 -> 10764.261 | E12: =D12*'Bank Inputs'!M11 -> 5259.7236 | F12: ='Bank Inputs'!F11-E12 -> 108847.53 | G12: =F12/'Bank Inputs'!E11 -> 0.16771235 | H12: =G12-'Bank Inputs'!R11 -> -0.008104186 | I12: ='Bank Inputs'!S11 -> 0.098 | J12: =G12-I12 -> 0.069712349 | K12: =IF(J12<0,"YES","no") -> no | L12: ='Bank Inputs'!P11*$F$4 -> 13333.638 | M12: =L12-E12 -> 8073.9142 | N12: =MAX(M12,0)*Assumptions!$C$14 -> 2422.1743 | O12: =M12-N12 -> 5651.74 | P12: =IF(O12>0,O12*Assumptions!$C$16,Assumptions!$C$17*0) -> 1695.522 | Q12: ='Bank Inputs'!F11+O12-P12 -> 118063.47 | R12: =Q12/'Bank Inputs'!E11 -> 0.18191228 | S12: =R12-I12 -> 0.083912279
A13: ='Bank Inputs'!B12 -> HSBC Continental Europe | B13: ='Bank Inputs'!C12 -> Core | C13: ='Bank Inputs'!L12+$D$4 -> 0.023525665 | D13: =$D$4*'Bank Inputs'!J12 -> 725.1791 | E13: =D13*'Bank Inputs'!M12 -> 190.63969 | F13: ='Bank Inputs'!F12-E13 -> 10270.652 | G13: =F13/'Bank Inputs'!E12 -> 0.15191006 | H13: =G13-'Bank Inputs'!R12 -> -0.0028196932 | I13: ='Bank Inputs'!S12 -> 0.097 | J13: =G13-I13 -> 0.054910064 | K13: =IF(J13<0,"YES","no") -> no | L13: ='Bank Inputs'!P12*$F$4 -> 996.056 | M13: =L13-E13 -> 805.41631 | N13: =MAX(M13,0)*Assumptions!$C$14 -> 241.62489 | O13: =M13-N13 -> 563.79142 | P13: =IF(O13>0,O13*Assumptions!$C$16,Assumptions!$C$17*0) -> 169.13743 | Q13: ='Bank Inputs'!F12+O13-P13 -> 10855.946 | R13: =Q13/'Bank Inputs'!E12 -> 0.16056696 | S13: =R13-I13 -> 0.063566963
A14: ='Bank Inputs'!B13 -> ING Groep | B14: ='Bank Inputs'!C13 -> Core | C14: ='Bank Inputs'!L13+$D$4 -> 0.022888308 | D14: =$D$4*'Bank Inputs'!J13 -> 6625.0565 | E14: =D14*'Bank Inputs'!M13 -> 2248.2802 | F14: ='Bank Inputs'!F13-E14 -> 42285.752 | G14: =F14/'Bank Inputs'!E13 -> 0.12592399 | H14: =G14-'Bank Inputs'!R13 -> -0.0066952201 | I14: ='Bank Inputs'!S13 -> 0.1087 | J14: =G14-I14 -> 0.017223991 | K14: =IF(J14<0,"YES","no") -> no | L14: ='Bank Inputs'!P13*$F$4 -> 8986.068 | M14: =L14-E14 -> 6737.7878 | N14: =MAX(M14,0)*Assumptions!$C$14 -> 2021.3363 | O14: =M14-N14 -> 4716.4514 | P14: =IF(O14>0,O14*Assumptions!$C$16,Assumptions!$C$17*0) -> 1414.9354 | Q14: ='Bank Inputs'!F13+O14-P14 -> 47835.548 | R14: =Q14/'Bank Inputs'!E13 -> 0.14245089 | S14: =R14-I14 -> 0.033750894
A15: ='Bank Inputs'!B14 -> Morgan Stanley Europe Holding SE | B15: ='Bank Inputs'!C14 -> Core | C15: ='Bank Inputs'!L14+$D$4 -> 0.0081844481 | D15: =$D$4*'Bank Inputs'!J14 -> 302.0946 | E15: =D15*'Bank Inputs'!M14 -> 109.50898 | F15: ='Bank Inputs'!F14-E15 -> 6181.2684 | G15: =F15/'Bank Inputs'!E14 -> 0.17685958 | H15: =G15-'Bank Inputs'!R14 -> -0.003133291 | I15: ='Bank Inputs'!S14 -> 0.0956 | J15: =G15-I15 -> 0.08125958 | K15: =IF(J15<0,"YES","no") -> no | L15: ='Bank Inputs'!P14*$F$4 -> 538.90771 | M15: =L15-E15 -> 429.39873 | N15: =MAX(M15,0)*Assumptions!$C$14 -> 128.81962 | O15: =M15-N15 -> 300.57911 | P15: =IF(O15>0,O15*Assumptions!$C$16,Assumptions!$C$17*0) -> 90.173733 | Q15: ='Bank Inputs'!F14+O15-P15 -> 6501.1828 | R15: =Q15/'Bank Inputs'!E14 -> 0.18601303 | S15: =R15-I15 -> 0.090413028
A16: ='Bank Inputs'!B15 -> Revolut Holdings Europe | B16: ='Bank Inputs'!C15 -> Reference case | C16: ='Bank Inputs'!L15+$D$4 -> 0.016026158 | D16: =$D$4*'Bank Inputs'!J15 -> 56.909006 | E16: =D16*'Bank Inputs'!M15 -> 45.835942 | F16: ='Bank Inputs'!F15-E16 -> 1251.3194 | G16: =F16/'Bank Inputs'!E15 -> 0.30216945 | H16: =G16-'Bank Inputs'!R15 -> -0.011068494 | I16: ='Bank Inputs'!S15 -> 0.0997 | J16: =G16-I16 -> 0.20246945 | K16: =IF(J16<0,"YES","no") -> no | L16: ='Bank Inputs'!P15*$F$4 -> 267.1336 | M16: =L16-E16 -> 221.29766 | N16: =MAX(M16,0)*Assumptions!$C$14 -> 66.389298 | O16: =M16-N16 -> 154.90836 | P16: =IF(O16>0,O16*Assumptions!$C$16,Assumptions!$C$17*0) -> 46.472509 | Q16: ='Bank Inputs'!F15+O16-P16 -> 1405.5912 | R16: =Q16/'Bank Inputs'!E15 -> 0.33942311 | S16: =R16-I16 -> 0.23972311
A19: S2 · 1-year adverse | C19: Shock | D19: =Assumptions!$C$27 -> 0.012 | E19: Horizon (yrs) | F19: =Assumptions!$D$27 -> 1
A20: Bank | B20: Role | C20: Stressed NPE ratio | D20: Incremental NPE | E20: Incremental provisions | F20: HEADLINE: Stressed CET1 | G20: Stressed CET1 ratio | H20: Change in ratio (pp) | I20: CET1 requirement | J20: Headroom (pp) | K20: Below requirement? | L20: Earnings over horizon | M20: Pre-tax result | N20: Tax | O20: Net result | P20: Distributions | Q20: Stressed CET1 (with earnings) | R20: Stressed CET1 ratio (with earnings) | S20: Headroom with earnings (pp)
A21: ='Bank Inputs'!B5 -> BAWAG Group | B21: ='Bank Inputs'!C5 -> Core | C21: ='Bank Inputs'!L5+$D$19 -> 0.025329488 | D21: =$D$19*'Bank Inputs'!J5 -> 598.97937 | E21: =D21*'Bank Inputs'!M5 -> 250.01753 | F21: ='Bank Inputs'!F5-E21 -> 2699.5464 | G21: =F21/'Bank Inputs'!E5 -> 0.11484772 | H21: =G21-'Bank Inputs'!R5 -> -0.010636581 | I21: ='Bank Inputs'!S5 -> 0.1033 | J21: =G21-I21 -> 0.011547719 | K21: =IF(J21<0,"YES","no") -> no | L21: ='Bank Inputs'!P5*$F$19 -> 1096.8442 | M21: =L21-E21 -> 846.82663 | N21: =MAX(M21,0)*Assumptions!$C$14 -> 254.04799 | O21: =M21-N21 -> 592.77864 | P21: =IF(O21>0,O21*Assumptions!$C$16,Assumptions!$C$17*0) -> 177.83359 | Q21: ='Bank Inputs'!F5+O21-P21 -> 3364.509 | R21: =Q21/'Bank Inputs'!E5 -> 0.14313745 | S21: =R21-I21 -> 0.039837447
A22: ='Bank Inputs'!B6 -> BNP Paribas | B22: ='Bank Inputs'!C6 -> Core | C22: ='Bank Inputs'!L6+$D$19 -> 0.039884921 | D22: =$D$19*'Bank Inputs'!J6 -> 11563.417 | E22: =D22*'Bank Inputs'!M6 -> 5608.8336 | F22: ='Bank Inputs'!F6-E22 -> 92671.731 | G22: =F22/'Bank Inputs'!E6 -> 0.11747707 | H22: =G22-'Bank Inputs'!R6 -> -0.0071101436 | I22: ='Bank Inputs'!S6 -> 0.1029 | J22: =G22-I22 -> 0.014577065 | K22: =IF(J22<0,"YES","no") -> no | L22: ='Bank Inputs'!P6*$F$19 -> 17297.345 | M22: =L22-E22 -> 11688.511 | N22: =MAX(M22,0)*Assumptions!$C$14 -> 3506.5534 | O22: =M22-N22 -> 8181.958 | P22: =IF(O22>0,O22*Assumptions!$C$16,Assumptions!$C$17*0) -> 2454.5874 | Q22: ='Bank Inputs'!F6+O22-P22 -> 104007.94 | R22: =Q22/'Bank Inputs'!E6 -> 0.13184762 | S22: =R22-I22 -> 0.028947618
A23: ='Bank Inputs'!B7 -> Banco Santander | B23: ='Bank Inputs'!C7 -> Core | C23: ='Bank Inputs'!L7+$D$19 -> 0.045462074 | D23: =$D$19*'Bank Inputs'!J7 -> 12883.046 | E23: =D23*'Bank Inputs'!M7 -> 5108.1042 | F23: ='Bank Inputs'!F7-E23 -> 76144.803 | G23: =F23/'Bank Inputs'!E7 -> 0.12168561 | H23: =G23-'Bank Inputs'!R7 -> -0.0081631674 | I23: ='Bank Inputs'!S7 -> 0.0967 | J23: =G23-I23 -> 0.024985609 | K23: =IF(J23<0,"YES","no") -> no | L23: ='Bank Inputs'!P7*$F$19 -> 18179.884 | M23: =L23-E23 -> 13071.78 | N23: =MAX(M23,0)*Assumptions!$C$14 -> 3921.5339 | O23: =M23-N23 -> 9150.2459 | P23: =IF(O23>0,O23*Assumptions!$C$16,Assumptions!$C$17*0) -> 2745.0738 | Q23: ='Bank Inputs'!F7+O23-P23 -> 87658.079 | R23: =Q23/'Bank Inputs'!E7 -> 0.14008476 | S23: =R23-I23 -> 0.043384765
A24: ='Bank Inputs'!B8 -> CEC Bank | B24: ='Bank Inputs'!C8 -> Core | C24: ='Bank Inputs'!L8+$D$19 -> 0.080841027 | D24: =$D$19*'Bank Inputs'!J8 -> 97.286288 | E24: =D24*'Bank Inputs'!M8 -> 52.834519 | F24: ='Bank Inputs'!F8-E24 -> 1247.7222 | G24: =F24/'Bank Inputs'!E8 -> 0.22995153 | H24: =G24-'Bank Inputs'!R8 -> -0.0097372462 | I24: ='Bank Inputs'!S8 -> 0.122 | J24: =G24-I24 -> 0.10795153 | K24: =IF(J24<0,"YES","no") -> no | L24: ='Bank Inputs'!P8*$F$19 -> 149.92356 | M24: =L24-E24 -> 97.089044 | N24: =MAX(M24,0)*Assumptions!$C$14 -> 29.126713 | O24: =M24-N24 -> 67.962331 | P24: =IF(O24>0,O24*Assumptions!$C$16,Assumptions!$C$17*0) -> 20.388699 | Q24: ='Bank Inputs'!F8+O24-P24 -> 1348.1304 | R24: =Q24/'Bank Inputs'!E8 -> 0.24845646 | S24: =R24-I24 -> 0.12645646
A25: ='Bank Inputs'!B9 -> Commerzbank | B25: ='Bank Inputs'!C9 -> Core | C25: ='Bank Inputs'!L9+$D$19 -> 0.02589597 | D25: =$D$19*'Bank Inputs'!J9 -> 4348.6097 | E25: =D25*'Bank Inputs'!M9 -> 1899.536 | F25: ='Bank Inputs'!F9-E25 -> 23742.454 | G25: =F25/'Bank Inputs'!E9 -> 0.13480496 | H25: =G25-'Bank Inputs'!R9 -> -0.01078519 | I25: ='Bank Inputs'!S9 -> 0.1031 | J25: =G25-I25 -> 0.031704958 | K25: =IF(J25<0,"YES","no") -> no | L25: ='Bank Inputs'!P9*$F$19 -> 3718.0263 | M25: =L25-E25 -> 1818.4903 | N25: =MAX(M25,0)*Assumptions!$C$14 -> 545.54709 | O25: =M25-N25 -> 1272.9432 | P25: =IF(O25>0,O25*Assumptions!$C$16,Assumptions!$C$17*0) -> 381.88296 | Q25: ='Bank Inputs'!F9+O25-P25 -> 26533.05 | R25: =Q25/'Bank Inputs'!E9 -> 0.15064941 | S25: =R25-I25 -> 0.047549411
A26: ='Bank Inputs'!B10 -> Deutsche Bank | B26: ='Bank Inputs'!C10 -> Core | C26: ='Bank Inputs'!L10+$D$19 -> 0.032353458 | D26: =$D$19*'Bank Inputs'!J10 -> 8793.3016 | E26: =D26*'Bank Inputs'!M10 -> 2737.2422 | F26: ='Bank Inputs'!F10-E26 -> 45784.331 | G26: =F26/'Bank Inputs'!E10 -> 0.1343417 | H26: =G26-'Bank Inputs'!R10 -> -0.0080316948 | I26: ='Bank Inputs'!S10 -> 0.1124 | J26: =G26-I26 -> 0.021941698 | K26: =IF(J26<0,"YES","no") -> no | L26: ='Bank Inputs'!P10*$F$19 -> 10487.088 | M26: =L26-E26 -> 7749.8455 | N26: =MAX(M26,0)*Assumptions!$C$14 -> 2324.9536 | O26: =M26-N26 -> 5424.8918 | P26: =IF(O26>0,O26*Assumptions!$C$16,Assumptions!$C$17*0) -> 1627.4675 | Q26: ='Bank Inputs'!F10+O26-P26 -> 52318.997 | R26: =Q26/'Bank Inputs'!E10 -> 0.1535159 | S26: =R26-I26 -> 0.041115904
A27: ='Bank Inputs'!B11 -> Groupe Crédit Agricole | B27: ='Bank Inputs'!C11 -> Core | C27: ='Bank Inputs'!L11+$D$19 -> 0.031644079 | D27: =$D$19*'Bank Inputs'!J11 -> 16146.392 | E27: =D27*'Bank Inputs'!M11 -> 7889.5853 | F27: ='Bank Inputs'!F11-E27 -> 106217.66 | G27: =F27/'Bank Inputs'!E11 -> 0.16366026 | H27: =G27-'Bank Inputs'!R11 -> -0.012156279 | I27: ='Bank Inputs'!S11 -> 0.098 | J27: =G27-I27 -> 0.065660256 | K27: =IF(J27<0,"YES","no") -> no | L27: ='Bank Inputs'!P11*$F$19 -> 13333.638 | M27: =L27-E27 -> 5444.0525 | N27: =MAX(M27,0)*Assumptions!$C$14 -> 1633.2157 | O27: =M27-N27 -> 3810.8367 | P27: =IF(O27>0,O27*Assumptions!$C$16,Assumptions!$C$17*0) -> 1143.251 | Q27: ='Bank Inputs'!F11+O27-P27 -> 116774.83 | R27: =Q27/'Bank Inputs'!E11 -> 0.17992675 | S27: =R27-I27 -> 0.081926753
A28: ='Bank Inputs'!B12 -> HSBC Continental Europe | B28: ='Bank Inputs'!C12 -> Core | C28: ='Bank Inputs'!L12+$D$19 -> 0.027525665 | D28: =$D$19*'Bank Inputs'!J12 -> 1087.7687 | E28: =D28*'Bank Inputs'!M12 -> 285.95953 | F28: ='Bank Inputs'!F12-E28 -> 10175.332 | G28: =F28/'Bank Inputs'!E12 -> 0.15050022 | H28: =G28-'Bank Inputs'!R12 -> -0.0042295398 | I28: ='Bank Inputs'!S12 -> 0.097 | J28: =G28-I28 -> 0.053500217 | K28: =IF(J28<0,"YES","no") -> no | L28: ='Bank Inputs'!P12*$F$19 -> 996.056 | M28: =L28-E28 -> 710.09647 | N28: =MAX(M28,0)*Assumptions!$C$14 -> 213.02894 | O28: =M28-N28 -> 497.06753 | P28: =IF(O28>0,O28*Assumptions!$C$16,Assumptions!$C$17*0) -> 149.12026 | Q28: ='Bank Inputs'!F12+O28-P28 -> 10809.239 | R28: =Q28/'Bank Inputs'!E12 -> 0.15987614 | S28: =R28-I28 -> 0.062876138
A29: ='Bank Inputs'!B13 -> ING Groep | B29: ='Bank Inputs'!C13 -> Core | C29: ='Bank Inputs'!L13+$D$19 -> 0.026888308 | D29: =$D$19*'Bank Inputs'!J13 -> 9937.5847 | E29: =D29*'Bank Inputs'!M13 -> 3372.4203 | F29: ='Bank Inputs'!F13-E29 -> 41161.612 | G29: =F29/'Bank Inputs'!E13 -> 0.12257638 | H29: =G29-'Bank Inputs'!R13 -> -0.01004283 | I29: ='Bank Inputs'!S13 -> 0.1087 | J29: =G29-I29 -> 0.013876381 | K29: =IF(J29<0,"YES","no") -> no | L29: ='Bank Inputs'!P13*$F$19 -> 8986.068 | M29: =L29-E29 -> 5613.6477 | N29: =MAX(M29,0)*Assumptions!$C$14 -> 1684.0943 | O29: =M29-N29 -> 3929.5534 | P29: =IF(O29>0,O29*Assumptions!$C$16,Assumptions!$C$17*0) -> 1178.866 | Q29: ='Bank Inputs'!F13+O29-P29 -> 47284.72 | R29: =Q29/'Bank Inputs'!E13 -> 0.14081056 | S29: =R29-I29 -> 0.032110565
A30: ='Bank Inputs'!B14 -> Morgan Stanley Europe Holding SE | B30: ='Bank Inputs'!C14 -> Core | C30: ='Bank Inputs'!L14+$D$19 -> 0.012184448 | D30: =$D$19*'Bank Inputs'!J14 -> 453.1419 | E30: =D30*'Bank Inputs'!M14 -> 164.26348 | F30: ='Bank Inputs'!F14-E30 -> 6126.5139 | G30: =F30/'Bank Inputs'!E14 -> 0.17529293 | H30: =G30-'Bank Inputs'!R14 -> -0.0046999365 | I30: ='Bank Inputs'!S14 -> 0.0956 | J30: =G30-I30 -> 0.079692934 | K30: =IF(J30<0,"YES","no") -> no | L30: ='Bank Inputs'!P14*$F$19 -> 538.90771 | M30: =L30-E30 -> 374.64424 | N30: =MAX(M30,0)*Assumptions!$C$14 -> 112.39327 | O30: =M30-N30 -> 262.25096 | P30: =IF(O30>0,O30*Assumptions!$C$16,Assumptions!$C$17*0) -> 78.675289 | Q30: ='Bank Inputs'!F14+O30-P30 -> 6474.3531 | R30: =Q30/'Bank Inputs'!E14 -> 0.18524537 | S30: =R30-I30 -> 0.089645371
A31: ='Bank Inputs'!B15 -> Revolut Holdings Europe | B31: ='Bank Inputs'!C15 -> Reference case | C31: ='Bank Inputs'!L15+$D$19 -> 0.020026158 | D31: =$D$19*'Bank Inputs'!J15 -> 85.363509 | E31: =D31*'Bank Inputs'!M15 -> 68.753913 | F31: ='Bank Inputs'!F15-E31 -> 1228.4015 | G31: =F31/'Bank Inputs'!E15 -> 0.2966352 | H31: =G31-'Bank Inputs'!R15 -> -0.016602741 | I31: ='Bank Inputs'!S15 -> 0.0997 | J31: =G31-I31 -> 0.1969352 | K31: =IF(J31<0,"YES","no") -> no | L31: ='Bank Inputs'!P15*$F$19 -> 267.1336 | M31: =L31-E31 -> 198.37969 | N31: =MAX(M31,0)*Assumptions!$C$14 -> 59.513907 | O31: =M31-N31 -> 138.86578 | P31: =IF(O31>0,O31*Assumptions!$C$16,Assumptions!$C$17*0) -> 41.659735 | Q31: ='Bank Inputs'!F15+O31-P31 -> 1394.3614 | R31: =Q31/'Bank Inputs'!E15 -> 0.33671133 | S31: =R31-I31 -> 0.23701133
A34: S3 · 3-year baseline | C34: Shock | D34: =Assumptions!$C$28 -> 0.024 | E34: Horizon (yrs) | F34: =Assumptions!$D$28 -> 3
A35: Bank | B35: Role | C35: Stressed NPE ratio | D35: Incremental NPE | E35: Incremental provisions | F35: HEADLINE: Stressed CET1 | G35: Stressed CET1 ratio | H35: Change in ratio (pp) | I35: CET1 requirement | J35: Headroom (pp) | K35: Below requirement? | L35: Earnings over horizon | M35: Pre-tax result | N35: Tax | O35: Net result | P35: Distributions | Q35: Stressed CET1 (with earnings) | R35: Stressed CET1 ratio (with earnings) | S35: Headroom with earnings (pp)
A36: ='Bank Inputs'!B5 -> BAWAG Group | B36: ='Bank Inputs'!C5 -> Core | C36: ='Bank Inputs'!L5+$D$34 -> 0.037329488 | D36: =$D$34*'Bank Inputs'!J5 -> 1197.9587 | E36: =D36*'Bank Inputs'!M5 -> 500.03506 | F36: ='Bank Inputs'!F5-E36 -> 2449.5289 | G36: =F36/'Bank Inputs'!E5 -> 0.10421114 | H36: =G36-'Bank Inputs'!R5 -> -0.021273161 | I36: ='Bank Inputs'!S5 -> 0.1033 | J36: =G36-I36 -> 0.00091113823 | K36: =IF(J36<0,"YES","no") -> no | L36: ='Bank Inputs'!P5*$F$34 -> 3290.5325 | M36: =L36-E36 -> 2790.4974 | N36: =MAX(M36,0)*Assumptions!$C$14 -> 837.14923 | O36: =M36-N36 -> 1953.3482 | P36: =IF(O36>0,O36*Assumptions!$C$16,Assumptions!$C$17*0) -> 586.00446 | Q36: ='Bank Inputs'!F5+O36-P36 -> 4316.9077 | R36: =Q36/'Bank Inputs'!E5 -> 0.18365567 | S36: =R36-I36 -> 0.080355668
A37: ='Bank Inputs'!B6 -> BNP Paribas | B37: ='Bank Inputs'!C6 -> Core | C37: ='Bank Inputs'!L6+$D$34 -> 0.051884921 | D37: =$D$34*'Bank Inputs'!J6 -> 23126.833 | E37: =D37*'Bank Inputs'!M6 -> 11217.667 | F37: ='Bank Inputs'!F6-E37 -> 87062.897 | G37: =F37/'Bank Inputs'!E6 -> 0.11036692 | H37: =G37-'Bank Inputs'!R6 -> -0.014220287 | I37: ='Bank Inputs'!S6 -> 0.1029 | J37: =G37-I37 -> 0.0074669219 | K37: =IF(J37<0,"YES","no") -> no | L37: ='Bank Inputs'!P6*$F$34 -> 51892.035 | M37: =L37-E37 -> 40674.368 | N37: =MAX(M37,0)*Assumptions!$C$14 -> 12202.31 | O37: =M37-N37 -> 28472.057 | P37: =IF(O37>0,O37*Assumptions!$C$16,Assumptions!$C$17*0) -> 8541.6172 | Q37: ='Bank Inputs'!F6+O37-P37 -> 118211 | R37: =Q37/'Bank Inputs'!E6 -> 0.14985241 | S37: =R37-I37 -> 0.046952407
A38: ='Bank Inputs'!B7 -> Banco Santander | B38: ='Bank Inputs'!C7 -> Core | C38: ='Bank Inputs'!L7+$D$34 -> 0.057462074 | D38: =$D$34*'Bank Inputs'!J7 -> 25766.093 | E38: =D38*'Bank Inputs'!M7 -> 10216.208 | F38: ='Bank Inputs'!F7-E38 -> 71036.698 | G38: =F38/'Bank Inputs'!E7 -> 0.11352244 | H38: =G38-'Bank Inputs'!R7 -> -0.016326335 | I38: ='Bank Inputs'!S7 -> 0.0967 | J38: =G38-I38 -> 0.016822442 | K38: =IF(J38<0,"YES","no") -> no | L38: ='Bank Inputs'!P7*$F$34 -> 54539.652 | M38: =L38-E38 -> 44323.444 | N38: =MAX(M38,0)*Assumptions!$C$14 -> 13297.033 | O38: =M38-N38 -> 31026.411 | P38: =IF(O38>0,O38*Assumptions!$C$16,Assumptions!$C$17*0) -> 9307.9232 | Q38: ='Bank Inputs'!F7+O38-P38 -> 102971.39 | R38: =Q38/'Bank Inputs'!E7 -> 0.16455669 | S38: =R38-I38 -> 0.067856692
A39: ='Bank Inputs'!B8 -> CEC Bank | B39: ='Bank Inputs'!C8 -> Core | C39: ='Bank Inputs'!L8+$D$34 -> 0.092841027 | D39: =$D$34*'Bank Inputs'!J8 -> 194.57258 | E39: =D39*'Bank Inputs'!M8 -> 105.66904 | F39: ='Bank Inputs'!F8-E39 -> 1194.8877 | G39: =F39/'Bank Inputs'!E8 -> 0.22021428 | H39: =G39-'Bank Inputs'!R8 -> -0.019474492 | I39: ='Bank Inputs'!S8 -> 0.122 | J39: =G39-I39 -> 0.098214284 | K39: =IF(J39<0,"YES","no") -> no | L39: ='Bank Inputs'!P8*$F$34 -> 449.77069 | M39: =L39-E39 -> 344.10165 | N39: =MAX(M39,0)*Assumptions!$C$14 -> 103.2305 | O39: =M39-N39 -> 240.87116 | P39: =IF(O39>0,O39*Assumptions!$C$16,Assumptions!$C$17*0) -> 72.261347 | Q39: ='Bank Inputs'!F8+O39-P39 -> 1469.1666 | R39: =Q39/'Bank Inputs'!E8 -> 0.27076307 | S39: =R39-I39 -> 0.14876307
A40: ='Bank Inputs'!B9 -> Commerzbank | B40: ='Bank Inputs'!C9 -> Core | C40: ='Bank Inputs'!L9+$D$34 -> 0.03789597 | D40: =$D$34*'Bank Inputs'!J9 -> 8697.2195 | E40: =D40*'Bank Inputs'!M9 -> 3799.0719 | F40: ='Bank Inputs'!F9-E40 -> 21842.918 | G40: =F40/'Bank Inputs'!E9 -> 0.12401977 | H40: =G40-'Bank Inputs'!R9 -> -0.021570379 | I40: ='Bank Inputs'!S9 -> 0.1031 | J40: =G40-I40 -> 0.020919768 | K40: =IF(J40<0,"YES","no") -> no | L40: ='Bank Inputs'!P9*$F$34 -> 11154.079 | M40: =L40-E40 -> 7355.0068 | N40: =MAX(M40,0)*Assumptions!$C$14 -> 2206.502 | O40: =M40-N40 -> 5148.5048 | P40: =IF(O40>0,O40*Assumptions!$C$16,Assumptions!$C$17*0) -> 1544.5514 | Q40: ='Bank Inputs'!F9+O40-P40 -> 29245.943 | R40: =Q40/'Bank Inputs'!E9 -> 0.16605268 | S40: =R40-I40 -> 0.062952682
A41: ='Bank Inputs'!B10 -> Deutsche Bank | B41: ='Bank Inputs'!C10 -> Core | C41: ='Bank Inputs'!L10+$D$34 -> 0.044353458 | D41: =$D$34*'Bank Inputs'!J10 -> 17586.603 | E41: =D41*'Bank Inputs'!M10 -> 5474.4845 | F41: ='Bank Inputs'!F10-E41 -> 43047.088 | G41: =F41/'Bank Inputs'!E10 -> 0.12631 | H41: =G41-'Bank Inputs'!R10 -> -0.01606339 | I41: ='Bank Inputs'!S10 -> 0.1124 | J41: =G41-I41 -> 0.013910003 | K41: =IF(J41<0,"YES","no") -> no | L41: ='Bank Inputs'!P10*$F$34 -> 31461.263 | M41: =L41-E41 -> 25986.779 | N41: =MAX(M41,0)*Assumptions!$C$14 -> 7796.0336 | O41: =M41-N41 -> 18190.745 | P41: =IF(O41>0,O41*Assumptions!$C$16,Assumptions!$C$17*0) -> 5457.2235 | Q41: ='Bank Inputs'!F10+O41-P41 -> 61255.094 | R41: =Q41/'Bank Inputs'!E10 -> 0.17973646 | S41: =R41-I41 -> 0.067336457
A42: ='Bank Inputs'!B11 -> Groupe Crédit Agricole | B42: ='Bank Inputs'!C11 -> Core | C42: ='Bank Inputs'!L11+$D$34 -> 0.043644079 | D42: =$D$34*'Bank Inputs'!J11 -> 32292.784 | E42: =D42*'Bank Inputs'!M11 -> 15779.171 | F42: ='Bank Inputs'!F11-E42 -> 98328.078 | G42: =F42/'Bank Inputs'!E11 -> 0.15150398 | H42: =G42-'Bank Inputs'!R11 -> -0.024312558 | I42: ='Bank Inputs'!S11 -> 0.098 | J42: =G42-I42 -> 0.053503977 | K42: =IF(J42<0,"YES","no") -> no | L42: ='Bank Inputs'!P11*$F$34 -> 40000.913 | M42: =L42-E42 -> 24221.743 | N42: =MAX(M42,0)*Assumptions!$C$14 -> 7266.5228 | O42: =M42-N42 -> 16955.22 | P42: =IF(O42>0,O42*Assumptions!$C$16,Assumptions!$C$17*0) -> 5086.566 | Q42: ='Bank Inputs'!F11+O42-P42 -> 125975.9 | R42: =Q42/'Bank Inputs'!E11 -> 0.19410377 | S42: =R42-I42 -> 0.096103766
A43: ='Bank Inputs'!B12 -> HSBC Continental Europe | B43: ='Bank Inputs'!C12 -> Core | C43: ='Bank Inputs'!L12+$D$34 -> 0.039525665 | D43: =$D$34*'Bank Inputs'!J12 -> 2175.5373 | E43: =D43*'Bank Inputs'!M12 -> 571.91907 | F43: ='Bank Inputs'!F12-E43 -> 9889.3726 | G43: =F43/'Bank Inputs'!E12 -> 0.14627068 | H43: =G43-'Bank Inputs'!R12 -> -0.0084590796 | I43: ='Bank Inputs'!S12 -> 0.097 | J43: =G43-I43 -> 0.049270677 | K43: =IF(J43<0,"YES","no") -> no | L43: ='Bank Inputs'!P12*$F$34 -> 2988.168 | M43: =L43-E43 -> 2416.2489 | N43: =MAX(M43,0)*Assumptions!$C$14 -> 724.87468 | O43: =M43-N43 -> 1691.3743 | P43: =IF(O43>0,O43*Assumptions!$C$16,Assumptions!$C$17*0) -> 507.41228 | Q43: ='Bank Inputs'!F12+O43-P43 -> 11645.254 | R43: =Q43/'Bank Inputs'!E12 -> 0.17224138 | S43: =R43-I43 -> 0.075241376
A44: ='Bank Inputs'!B13 -> ING Groep | B44: ='Bank Inputs'!C13 -> Core | C44: ='Bank Inputs'!L13+$D$34 -> 0.038888308 | D44: =$D$34*'Bank Inputs'!J13 -> 19875.169 | E44: =D44*'Bank Inputs'!M13 -> 6744.8407 | F44: ='Bank Inputs'!F13-E44 -> 37789.192 | G44: =F44/'Bank Inputs'!E13 -> 0.11253355 | H44: =G44-'Bank Inputs'!R13 -> -0.02008566 | I44: ='Bank Inputs'!S13 -> 0.1087 | J44: =G44-I44 -> 0.0038335512 | K44: =IF(J44<0,"YES","no") -> no | L44: ='Bank Inputs'!P13*$F$34 -> 26958.204 | M44: =L44-E44 -> 20213.363 | N44: =MAX(M44,0)*Assumptions!$C$14 -> 6064.009 | O44: =M44-N44 -> 14149.354 | P44: =IF(O44>0,O44*Assumptions!$C$16,Assumptions!$C$17*0) -> 4244.8063 | Q44: ='Bank Inputs'!F13+O44-P44 -> 54438.58 | R44: =Q44/'Bank Inputs'!E13 -> 0.16211426 | S44: =R44-I44 -> 0.053414258
A45: ='Bank Inputs'!B14 -> Morgan Stanley Europe Holding SE | B45: ='Bank Inputs'!C14 -> Core | C45: ='Bank Inputs'!L14+$D$34 -> 0.024184448 | D45: =$D$34*'Bank Inputs'!J14 -> 906.28381 | E45: =D45*'Bank Inputs'!M14 -> 328.52695 | F45: ='Bank Inputs'!F14-E45 -> 5962.2505 | G45: =F45/'Bank Inputs'!E14 -> 0.170593 | H45: =G45-'Bank Inputs'!R14 -> -0.0093998731 | I45: ='Bank Inputs'!S14 -> 0.0956 | J45: =G45-I45 -> 0.074992998 | K45: =IF(J45<0,"YES","no") -> no | L45: ='Bank Inputs'!P14*$F$34 -> 1616.7231 | M45: =L45-E45 -> 1288.1962 | N45: =MAX(M45,0)*Assumptions!$C$14 -> 386.45885 | O45: =M45-N45 -> 901.73733 | P45: =IF(O45>0,O45*Assumptions!$C$16,Assumptions!$C$17*0) -> 270.5212 | Q45: ='Bank Inputs'!F14+O45-P45 -> 6921.9935 | R45: =Q45/'Bank Inputs'!E14 -> 0.19805334 | S45: =R45-I45 -> 0.10245334
...

Sheet Summary
A1: Summary: headroom to CET1 requirement (pp of RWA)
A2: Negative headroom = stressed CET1 ratio below the bank's requirement (distribution restrictions would apply).
A3: HEADLINE: instant loss absorption (no earnings offset)
A4: Bank | B4: Role | C4: CET1 ratio today | D4: Requirement | E4: Headroom today | F4: S1 1-yr baseline | G4: S2 1-yr adverse | H4: S3 3-yr baseline | I4: S4 3-yr adverse | J4: Stressed CET1 ratio, S4 | K4: Change in ratio S4 (pp)
A5: ='Bank Inputs'!B5 -> BAWAG Group | B5: ='Bank Inputs'!C5 -> Core | C5: ='Bank Inputs'!R5 -> 0.1254843 | D5: ='Bank Inputs'!S5 -> 0.1033 | E5: =C5-D5 -> 0.022184299 | F5: =Stress!J6 -> 0.015093246 | G5: =Stress!J21 -> 0.011547719 | H5: =Stress!J36 -> 0.00091113823 | I5: =Stress!J51 -> -0.014157351 | J5: =Stress!G51 -> 0.089142649 | K5: =Stress!G51-'Bank Inputs'!R5 -> -0.03634165
A6: ='Bank Inputs'!B6 -> BNP Paribas | B6: ='Bank Inputs'!C6 -> Core | C6: ='Bank Inputs'!R6 -> 0.12458721 | D6: ='Bank Inputs'!S6 -> 0.1029 | E6: =C6-D6 -> 0.021687209 | F6: =Stress!J7 -> 0.016947113 | G6: =Stress!J22 -> 0.014577065 | H6: =Stress!J37 -> 0.0074669219 | I6: =Stress!J52 -> -0.0026057815 | J6: =Stress!G52 -> 0.10029422 | K6: =Stress!G52-'Bank Inputs'!R6 -> -0.024292991
A7: ='Bank Inputs'!B7 -> Banco Santander | B7: ='Bank Inputs'!C7 -> Core | C7: ='Bank Inputs'!R7 -> 0.12984878 | D7: ='Bank Inputs'!S7 -> 0.0967 | E7: =C7-D7 -> 0.033148777 | F7: =Stress!J8 -> 0.027706665 | G7: =Stress!J23 -> 0.024985609 | H7: =Stress!J38 -> 0.016822442 | I7: =Stress!J53 -> 0.0052579548 | J7: =Stress!G53 -> 0.10195795 | K7: =Stress!G53-'Bank Inputs'!R7 -> -0.027890822
A8: ='Bank Inputs'!B8 -> CEC Bank | B8: ='Bank Inputs'!C8 -> Core | C8: ='Bank Inputs'!R8 -> 0.23968878 | D8: ='Bank Inputs'!S8 -> 0.122 | E8: =C8-D8 -> 0.11768878 | F8: =Stress!J9 -> 0.11119728 | G8: =Stress!J24 -> 0.10795153 | H8: =Stress!J39 -> 0.098214284 | I8: =Stress!J54 -> 0.084419851 | J8: =Stress!G54 -> 0.20641985 | K8: =Stress!G54-'Bank Inputs'!R8 -> -0.033268925
A9: ='Bank Inputs'!B9 -> Commerzbank | B9: ='Bank Inputs'!C9 -> Core | C9: ='Bank Inputs'!R9 -> 0.14559015 | D9: ='Bank Inputs'!S9 -> 0.1031 | E9: =C9-D9 -> 0.042490148 | F9: =Stress!J10 -> 0.035300021 | G9: =Stress!J25 -> 0.031704958 | H9: =Stress!J40 -> 0.020919768 | I9: =Stress!J55 -> 0.0056407498 | J9: =Stress!G55 -> 0.10874075 | K9: =Stress!G55-'Bank Inputs'!R9 -> -0.036849398
A10: ='Bank Inputs'!B10 -> Deutsche Bank | B10: ='Bank Inputs'!C10 -> Core | C10: ='Bank Inputs'!R10 -> 0.14237339 | D10: ='Bank Inputs'!S10 -> 0.1124 | E10: =C10-D10 -> 0.029973393 | F10: =Stress!J11 -> 0.02461893 | G10: =Stress!J26 -> 0.021941698 | H10: =Stress!J41 -> 0.013910003 | I10: =Stress!J56 -> 0.0025317691 | J10: =Stress!G56 -> 0.11493177 | K10: =Stress!G56-'Bank Inputs'!R10 -> -0.027441624
A11: ='Bank Inputs'!B11 -> Groupe Crédit Agricole | B11: ='Bank Inputs'!C11 -> Core | C11: ='Bank Inputs'!R11 -> 0.17581654 | D11: ='Bank Inputs'!S11 -> 0.098 | E11: =C11-D11 -> 0.077816535 | F11: =Stress!J12 -> 0.069712349 | G11: =Stress!J27 -> 0.065660256 | H11: =Stress!J42 -> 0.053503977 | I11: =Stress!J57 -> 0.036282582 | J11: =Stress!G57 -> 0.13428258 | K11: =Stress!G57-'Bank Inputs'!R11 -> -0.041533953
A12: ='Bank Inputs'!B12 -> HSBC Continental Europe | B12: ='Bank Inputs'!C12 -> Core | C12: ='Bank Inputs'!R12 -> 0.15472976 | D12: ='Bank Inputs'!S12 -> 0.097 | E12: =C12-D12 -> 0.057729757 | F12: =Stress!J13 -> 0.054910064 | G12: =Stress!J28 -> 0.053500217 | H12: =Stress!J43 -> 0.049270677 | I12: =Stress!J58 -> 0.043278829 | J12: =Stress!G58 -> 0.14027883 | K12: =Stress!G58-'Bank Inputs'!R12 -> -0.014450928
A13: ='Bank Inputs'!B13 -> ING Groep | B13: ='Bank Inputs'!C13 -> Core | C13: ='Bank Inputs'!R13 -> 0.13261921 | D13: ='Bank Inputs'!S13 -> 0.1087 | E13: =C13-D13 -> 0.023919212 | F13: =Stress!J14 -> 0.017223991 | G13: =Stress!J29 -> 0.013876381 | H13: =Stress!J44 -> 0.0038335512 | I13: =Stress!J59 -> -0.010393792 | J13: =Stress!G59 -> 0.098306208 | K13: =Stress!G59-'Bank Inputs'!R13 -> -0.034313003
A14: ='Bank Inputs'!B14 -> Morgan Stanley Europe Holding SE | B14: ='Bank Inputs'!C14 -> Core | C14: ='Bank Inputs'!R14 -> 0.17999287 | D14: ='Bank Inputs'!S14 -> 0.0956 | E14: =C14-D14 -> 0.084392871 | F14: =Stress!J15 -> 0.08125958 | G14: =Stress!J30 -> 0.079692934 | H14: =Stress!J45 -> 0.074992998 | I14: =Stress!J60 -> 0.068334754 | J14: =Stress!G60 -> 0.16393475 | K14: =Stress!G60-'Bank Inputs'!R14 -> -0.016058116
A15: ='Bank Inputs'!B15 -> Revolut Holdings Europe | B15: ='Bank Inputs'!C15 -> Reference case | C15: ='Bank Inputs'!R15 -> 0.31323795 | D15: ='Bank Inputs'!S15 -> 0.0997 | E15: =C15-D15 -> 0.21353795 | F15: =Stress!J16 -> 0.20246945 | G15: =Stress!J31 -> 0.1969352 | H15: =Stress!J46 -> 0.18033246 | I15: =Stress!J61 -> 0.15681191 | J15: =Stress!G61 -> 0.25651191 | K15: =Stress!G61-'Bank Inputs'!R15 -> -0.056726031
A17: Median, core banks | C17: =MEDIAN(C5:C14) -> 0.14398177 | D17: =MEDIAN(D5:D14) -> 0.103 | E17: =MEDIAN(E5:E14) -> 0.037819462 | F17: =MEDIAN(F5:F14) -> 0.031503343 | G17: =MEDIAN(G5:G14) -> 0.028345284 | H17: =MEDIAN(H5:H14) -> 0.018871105 | I17: =MEDIAN(I5:I14) -> 0.0054493523 | J17: =MEDIAN(J5:J14) -> 0.11183626 | K17: =MEDIAN(K5:K14) -> -0.030579873
A18: Minimum, core banks | C18: =MIN(C5:C14) -> 0.12458721 | D18: =MIN(D5:D14) -> 0.0956 | E18: =MIN(E5:E14) -> 0.021687209 | F18: =MIN(F5:F14) -> 0.015093246 | G18: =MIN(G5:G14) -> 0.011547719 | H18: =MIN(H5:H14) -> 0.00091113823 | I18: =MIN(I5:I14) -> -0.014157351 | J18: =MIN(J5:J14) -> 0.089142649 | K18: =MIN(K5:K14) -> -0.041533953
A19: Core banks below requirement | E19: =COUNTIF(E5:E14,"<0") -> 0 | F19: =COUNTIF(F5:F14,"<0") -> 0 | G19: =COUNTIF(G5:G14,"<0") -> 0 | H19: =COUNTIF(H5:H14,"<0") -> 0 | I19: =COUNTIF(I5:I14,"<0") -> 3
A20: Core banks with headroom < 1 pp | E20: =COUNTIF(E5:E14,"<0.01") -> 0 | F20: =COUNTIF(F5:F14,"<0.01") -> 0 | G20: =COUNTIF(G5:G14,"<0.01") -> 0 | H20: =COUNTIF(H5:H14,"<0.01") -> 3 | I20: =COUNTIF(I5:I14,"<0.01") -> 6
A22: SECOND LAYER: with earnings offset (optimistic, revenues not stressed; see Notes L2)
A23: Bank | B23: Role | C23: CET1 ratio today | D23: Requirement | E23: Headroom today | F23: S1 1-yr baseline | G23: S2 1-yr adverse | H23: S3 3-yr baseline | I23: S4 3-yr adverse | J23: Stressed CET1 ratio, S4 | K23: Change in ratio S4 (pp)
A24: ='Bank Inputs'!B5 -> BAWAG Group | B24: ='Bank Inputs'!C5 -> Core | C24: ='Bank Inputs'!R5 -> 0.1254843 | D24: ='Bank Inputs'!S5 -> 0.1033 | E24: =C24-D24 -> 0.022184299 | F24: =Stress!S6 -> 0.041574756 | G24: =Stress!S21 -> 0.039837447 | H24: =Stress!S36 -> 0.080355668 | I24: =Stress!S51 -> 0.072972108 | J24: =Stress!R51 -> 0.17627211 | K24: =Stress!R51-'Bank Inputs'!R5 -> 0.050787809
A25: ='Bank Inputs'!B6 -> BNP Paribas | B25: ='Bank Inputs'!C6 -> Core | C25: ='Bank Inputs'!R6 -> 0.12458721 | D25: ='Bank Inputs'!S6 -> 0.1029 | E25: =C25-D25 -> 0.021687209 | F25: =Stress!S7 -> 0.030108942 | G25: =Stress!S22 -> 0.028947618 | H25: =Stress!S37 -> 0.046952407 | I25: =Stress!S52 -> 0.042016782 | J25: =Stress!R52 -> 0.14491678 | K25: =Stress!R52-'Bank Inputs'!R6 -> 0.020329573
A26: ='Bank Inputs'!B7 -> Banco Santander | B26: ='Bank Inputs'!C7 -> Core | C26: ='Bank Inputs'!R7 -> 0.12984878 | D26: ='Bank Inputs'!S7 -> 0.0967 | E26: =C26-D26 -> 0.033148777 | F26: =Stress!S8 -> 0.044718082 | G26: =Stress!S23 -> 0.043384765 | H26: =Stress!S38 -> 0.067856692 | I26: =Stress!S53 -> 0.062190094 | J26: =Stress!R53 -> 0.15889009 | K26: =Stress!R53-'Bank Inputs'!R7 -> 0.029041317
A27: ='Bank Inputs'!B8 -> CEC Bank | B27: ='Bank Inputs'!C8 -> Core | C27: ='Bank Inputs'!R8 -> 0.23968878 | D27: ='Bank Inputs'!S8 -> 0.122 | E27: =C27-D27 -> 0.11768878 | F27: =Stress!S9 -> 0.12804687 | G27: =Stress!S24 -> 0.12645646 | H27: =Stress!S39 -> 0.14876307 | I27: =Stress!S54 -> 0.1420038 | J27: =Stress!R54 -> 0.2640038 | K27: =Stress!R54-'Bank Inputs'!R8 -> 0.024315019
A28: ='Bank Inputs'!B9 -> Commerzbank | B28: ='Bank Inputs'!C9 -> Core | C28: ='Bank Inputs'!R9 -> 0.14559015 | D28: ='Bank Inputs'!S9 -> 0.1031 | E28: =C28-D28 -> 0.042490148 | F28: =Stress!S10 -> 0.049310992 | G28: =Stress!S25 -> 0.047549411 | H28: =Stress!S40 -> 0.062952682 | I28: =Stress!S55 -> 0.055465963 | J28: =Stress!R55 -> 0.15856596 | K28: =Stress!R55-'Bank Inputs'!R9 -> 0.012975815
A29: ='Bank Inputs'!B10 -> Deutsche Bank | B29: ='Bank Inputs'!C10 -> Core | C29: ='Bank Inputs'!R10 -> 0.14237339 | D29: ='Bank Inputs'!S10 -> 0.1124 | E29: =C29-D29 -> 0.029973393 | F29: =Stress!S11 -> 0.042427748 | G29: =Stress!S26 -> 0.041115904 | H29: =Stress!S41 -> 0.067336457 | I29: =Stress!S56 -> 0.061761123 | J29: =Stress!R56 -> 0.17416112 | K29: =Stress!R56-'Bank Inputs'!R10 -> 0.03178773
A30: ='Bank Inputs'!B11 -> Groupe Crédit Agricole | B30: ='Bank Inputs'!C11 -> Core | C30: ='Bank Inputs'!R11 -> 0.17581654 | D30: ='Bank Inputs'!S11 -> 0.098 | E30: =C30-D30 -> 0.077816535 | F30: =Stress!S12 -> 0.083912279 | G30: =Stress!S27 -> 0.081926753 | H30: =Stress!S42 -> 0.096103766 | I30: =Stress!S57 -> 0.087665282 | J30: =Stress!R57 -> 0.18566528 | K30: =Stress!R57-'Bank Inputs'!R11 -> 0.0098487472
A31: ='Bank Inputs'!B12 -> HSBC Continental Europe | B31: ='Bank Inputs'!C12 -> Core | C31: ='Bank Inputs'!R12 -> 0.15472976 | D31: ='Bank Inputs'!S12 -> 0.097 | E31: =C31-D31 -> 0.057729757 | F31: =Stress!S13 -> 0.063566963 | G31: =Stress!S28 -> 0.062876138 | H31: =Stress!S43 -> 0.075241376 | I31: =Stress!S58 -> 0.07230537 | J31: =Stress!R58 -> 0.16930537 | K31: =Stress!R58-'Bank Inputs'!R12 -> 0.014575613
A32: ='Bank Inputs'!B13 -> ING Groep | B32: ='Bank Inputs'!C13 -> Core | C32: ='Bank Inputs'!R13 -> 0.13261921 | D32: ='Bank Inputs'!S13 -> 0.1087 | E32: =C32-D32 -> 0.023919212 | F32: =Stress!S14 -> 0.033750894 | G32: =Stress!S29 -> 0.032110565 | H32: =Stress!S44 -> 0.053414258 | I32: =Stress!S59 -> 0.04644286 | J32: =Stress!R59 -> 0.15514286 | K32: =Stress!R59-'Bank Inputs'!R13 -> 0.022523648
A33: ='Bank Inputs'!B14 -> Morgan Stanley Europe Holding SE | B33: ='Bank Inputs'!C14 -> Core | C33: ='Bank Inputs'!R14 -> 0.17999287 | D33: ='Bank Inputs'!S14 -> 0.0956 | E33: =C33-D33 -> 0.084392871 | F33: =Stress!S15 -> 0.090413028 | G33: =Stress!S30 -> 0.089645371 | H33: =Stress!S45 -> 0.10245334 | I33: =Stress!S60 -> 0.099190802 | J33: =Stress!R60 -> 0.1947908 | K33: =Stress!R60-'Bank Inputs'!R14 -> 0.014797932
A34: ='Bank Inputs'!B15 -> Revolut Holdings Europe | B34: ='Bank Inputs'!C15 -> Reference case | C34: ='Bank Inputs'!R15 -> 0.31323795 | D34: ='Bank Inputs'!S15 -> 0.0997 | E34: =C34-D34 -> 0.21353795 | F34: =Stress!S16 -> 0.23972311 | G34: =Stress!S31 -> 0.23701133 | H34: =Stress!S46 -> 0.29209343 | I34: =Stress!S61 -> 0.28056836 | J34: =Stress!R61 -> 0.38026836 | K34: =Stress!R61-'Bank Inputs'!R15 -> 0.067030419
A36: Median, core banks | C36: =MEDIAN(C24:C33) -> 0.14398177 | D36: =MEDIAN(D24:D33) -> 0.103 | E36: =MEDIAN(E24:E33) -> 0.037819462 | F36: =MEDIAN(F24:F33) -> 0.047014537 | G36: =MEDIAN(G24:G33) -> 0.045467088 | H36: =MEDIAN(H24:H33) -> 0.071549034 | I36: =MEDIAN(I24:I33) -> 0.067247732 | J36: =MEDIAN(J24:J33) -> 0.17173325 | K36: =MEDIAN(K24:K33) -> 0.021426611
A37: Minimum, core banks | C37: =MIN(C24:C33) -> 0.12458721 | D37: =MIN(D24:D33) -> 0.0956 | E37: =MIN(E24:E33) -> 0.021687209 | F37: =MIN(F24:F33) -> 0.030108942 | G37: =MIN(G24:G33) -> 0.028947618 | H37: =MIN(H24:H33) -> 0.046952407 | I37: =MIN(I24:I33) -> 0.042016782 | J37: =MIN(J24:J33) -> 0.14491678 | K37: =MIN(K24:K33) -> 0.0098487472
A38: Core banks below requirement | E38: =COUNTIF(E24:E33,"<0") -> 0 | F38: =COUNTIF(F24:F33,"<0") -> 0 | G38: =COUNTIF(G24:G33,"<0") -> 0 | H38: =COUNTIF(H24:H33,"<0") -> 0 | I38: =COUNTIF(I24:I33,"<0") -> 0
A39: Core banks with headroom < 1 pp | E39: =COUNTIF(E24:E33,"<0.01") -> 0 | F39: =COUNTIF(F24:F33,"<0.01") -> 0 | G39: =COUNTIF(G24:G33,"<0.01") -> 0 | H39: =COUNTIF(H24:H33,"<0.01") -> 0 | I39: =COUNTIF(I24:I33,"<0.01") -> 0
A41: Benchmark: ECB 2025 adverse aggregate CET1 depletion 4.0 pp over 3 years (all risk types, 96 banks), of which loan losses 5.0 pp, offset by net revenues 4.8 pp. This model captures the credit-loss channel only.

Sheet Sensitivity
A1: Sensitivity of 3-year adverse headroom (pp of RWA)
A2: Each column recomputes the chain with one lever changed; all other assumptions as on the Assumptions sheet.
A4: Shock step | B4: 0.003 | C4: Coverage step | D4: 0.1 | E4: Alt. payout | F4: 0.5
A6: HEADLINE view: instant loss absorption
A7: Bank | B7: Role | C7: Base case | D7: Shock −step | E7: Shock +step | F7: Coverage −step | G7: Coverage +step
A8: ='Bank Inputs'!B5 -> BAWAG Group | B8: ='Bank Inputs'!C5 -> Core | C8: =('Bank Inputs'!F5-(Assumptions!$C$7)*'Bank Inputs'!J5*('Bank Inputs'!M5))/'Bank Inputs'!E5-'Bank Inputs'!S5 -> -0.014157351 | D8: =('Bank Inputs'!F5-(Assumptions!$C$7-$B$4)*'Bank Inputs'!J5*('Bank Inputs'!M5))/'Bank Inputs'!E5-'Bank Inputs'!S5 -> -0.011498206 | E8: =('Bank Inputs'!F5-(Assumptions!$C$7+$B$4)*'Bank Inputs'!J5*('Bank Inputs'!M5))/'Bank Inputs'!E5-'Bank Inputs'!S5 -> -0.016816496 | F8: =('Bank Inputs'!F5-(Assumptions!$C$7)*'Bank Inputs'!J5*(MAX('Bank Inputs'!M5-$D$4,0)))/'Bank Inputs'!E5-'Bank Inputs'!S5 -> -0.0054508018 | G8: =('Bank Inputs'!F5-(Assumptions!$C$7)*'Bank Inputs'!J5*(MIN('Bank Inputs'!M5+$D$4,1)))/'Bank Inputs'!E5-'Bank Inputs'!S5 -> -0.0228639
A9: ='Bank Inputs'!B6 -> BNP Paribas | B9: ='Bank Inputs'!C6 -> Core | C9: =('Bank Inputs'!F6-(Assumptions!$C$7)*'Bank Inputs'!J6*('Bank Inputs'!M6))/'Bank Inputs'!E6-'Bank Inputs'!S6 -> -0.0026057815 | D9: =('Bank Inputs'!F6-(Assumptions!$C$7-$B$4)*'Bank Inputs'!J6*('Bank Inputs'!M6))/'Bank Inputs'!E6-'Bank Inputs'!S6 -> -0.00082824564 | E9: =('Bank Inputs'!F6-(Assumptions!$C$7+$B$4)*'Bank Inputs'!J6*('Bank Inputs'!M6))/'Bank Inputs'!E6-'Bank Inputs'!S6 -> -0.0043833174 | F9: =('Bank Inputs'!F6-(Assumptions!$C$7)*'Bank Inputs'!J6*(MAX('Bank Inputs'!M6-$D$4,0)))/'Bank Inputs'!E6-'Bank Inputs'!S6 -> 0.0024025677 | G9: =('Bank Inputs'!F6-(Assumptions!$C$7)*'Bank Inputs'!J6*(MIN('Bank Inputs'!M6+$D$4,1)))/'Bank Inputs'!E6-'Bank Inputs'!S6 -> -0.0076141308
A10: ='Bank Inputs'!B7 -> Banco Santander | B10: ='Bank Inputs'!C7 -> Core | C10: =('Bank Inputs'!F7-(Assumptions!$C$7)*'Bank Inputs'!J7*('Bank Inputs'!M7))/'Bank Inputs'!E7-'Bank Inputs'!S7 -> 0.0052579548 | D10: =('Bank Inputs'!F7-(Assumptions!$C$7-$B$4)*'Bank Inputs'!J7*('Bank Inputs'!M7))/'Bank Inputs'!E7-'Bank Inputs'!S7 -> 0.0072987467 | E10: =('Bank Inputs'!F7-(Assumptions!$C$7+$B$4)*'Bank Inputs'!J7*('Bank Inputs'!M7))/'Bank Inputs'!E7-'Bank Inputs'!S7 -> 0.0032171629 | F10: =('Bank Inputs'!F7-(Assumptions!$C$7)*'Bank Inputs'!J7*(MAX('Bank Inputs'!M7-$D$4,0)))/'Bank Inputs'!E7-'Bank Inputs'!S7 -> 0.012292243 | G10: =('Bank Inputs'!F7-(Assumptions!$C$7)*'Bank Inputs'!J7*(MIN('Bank Inputs'!M7+$D$4,1)))/'Bank Inputs'!E7-'Bank Inputs'!S7 -> -0.001776333
